<?xml version="1.0"?>
<robot xmlns:xacro="http://www.ros.org/wiki/xacro" name="mobot_wheel_trans">

    <xacro:macro name="wheel" params="prefix reflect">
        <link name="${prefix}_wheel">
            <visual>
                <geometry>
                    <cylinder radius="${wheelrad}" length="${wheelwidth}"/>
                </geometry>
            </visual>
            <collision>
                <geometry>
                    <cylinder radius="${wheelrad}" length="${wheelwidth}"/>
                </geometry>           
            </collision>
            <inertial>
                <mass value="1"/>
                <inertia ixx="0.1" ixy="0.0" ixz="0.0"
                         iyy="0.1" iyz="0.0"
                         izz="0.1"/>
            </inertial>
        </link>

        <joint name="${prefix}_wheel_joint" type="continuous">
            <axis xyz="0 0 1"/>
            <parent link="base_link"/>
            <child link="${prefix}_wheel"/>
            <origin xyz="0 ${reflect*wheeldist/2.0} ${wheelrad}" rpy="0 ${M_PI/2} ${M_PI/2}"/>
            <limit effort="100" velocity="15"/>
            <joint_properties damping="0.0" friction="0.0"/>
        </joint>
    </xacro:macro>

    <xacro:wheel prefix="left" reflect="1"/>
    <xacro:wheel prefix="right" reflect="-1"/>

</robot>